Workbook

Sheet اقرأني
A1: مراجعة لغة صقّور — للمعلّمة / المعلّم Saqqour language review, for the Arabic teacher
A2: شكرًا لمساعدتك! صقّور مساعد ذكاء اصطناعي يعلّم الأطفال العربية. نريد التأكد أن كل جملة يقولها صحيحة وطبيعية. Thank you for helping! Saqqour is an AI helper that teaches children Arabic. We want every line it says to be correct and natural.
A3: القاعدة الأساسية The core rule
A4: كلام صقّور المنطوق يكون باللهجة اليومية التي اختارها الطفل. القراءة والكتابة تكون بالفصحى. لا نخلط اللهجة والفصحى في الجملة الواحدة أبدًا. Spoken lines are in the everyday dialect the child chose. Reading and writing are in Fusha. Dialect and Fusha are never mixed in one line.
A5: كيف تراجع كل سطر How to review each line
A6: 1. اختر من عمود «الحالة» القائمة المنسدلة: ✔ سليم · ✖ يحتاج تصحيح · ? غير متأكد 1. In the Status column pick from the dropdown: ✔ ok · ✖ fix · ? unsure
A7: 2. إذا اخترت ✖ اكتب الجملة الصحيحة في عمود «الجملة المصحّحة» (بالتشكيل إن أمكن). 2. If you choose ✖, write the corrected line in the Corrected line column (with vowel marks if you can).
A8: 3. في «ملاحظات المعلّم» اذكر إن كانت كلمة من لهجة أخرى، أو إن كانت الفصحى غير صحيحة، أو إن كان صيغة الولد/البنت خطأ. 3. In Teacher notes, say if a word is from the wrong dialect, if the Fusha is wrong, or if the boy/girl form is wrong.
A9: 4. الأسطر المظللة بالأصفر (أولوية) هي التي نحن غير متأكدين منها أكثر، ابدأ بها من فضلك. عمود «سبب المراجعة» يشرح شكّنا. 4. Yellow rows (priority) are the ones we are least sure about; please start with them. The "Why flagged" column explains our doubt.
A10: ما في الملف What is in this file
A11: • ورقة لكل لهجة (الإماراتية، السعودية، اللبنانية، السورية، الأردنية، المصرية) وورقة للفصحى: جمل الصفحة الرئيسية، جمل الدرس، الرد على الأسئلة خارج العربية، الرفض اللطيف، وجمل مساعد الواجب. • One sheet per dialect plus Fusha: home-screen lines, lesson lines, off-topic redirects, gentle refusals and homework-helper lines.
A12: • «ردود حية»: ردود حقيقية من صقّور على رسائل تجريبية لأطفال (لا توجد أسماء حقيقية). • "Live replies": real replies from Saqqour to test messages written as a child would (no real names).
... A22: • في الأوراق الجديدة أيضًا: اختر ✔ أو ✖ أو ? من عمود «الحالة»، واكتب التصحيح في عمود «الجملة المصحّحة» (المظلّل بالأخضر الفاتح). • In the new sheets too: pick ✔ / ✖ / ? in Status and write your correction in the Corrected line column (light green).

Sheet الملخص
A1: الورقة Sheet | B1: عدد الأسطر Rows | C1: أولوية ★ Priority | D1: ✔ سليم ok | E1: ✖ تصحيح fix | F1: ? غير متأكد unsure | G1: لم يُراجع بعد not reviewed yet
A2: الإماراتية (Emirati) | B2: 120 | C2: 4 | D2: =COUNTIF('الإماراتية'!H2:H121,"✔") | E2: =COUNTIF('الإماراتية'!H2:H121,"✖") | F2: =COUNTIF('الإماراتية'!H2:H121,"?") | G2: =B2-D2-E2-F2
A3: السعودية (Saudi) | B3: 134 | C3: 24 | D3: =COUNTIF('السعودية'!H2:H135,"✔") | E3: =COUNTIF('السعودية'!H2:H135,"✖") | F3: =COUNTIF('السعودية'!H2:H135,"?") | G3: =B3-D3-E3-F3
A4: اللبنانية (Lebanese) | B4: 118 | C4: 4 | D4: =COUNTIF('اللبنانية'!H2:H119,"✔") | E4: =COUNTIF('اللبنانية'!H2:H119,"✖") | F4: =COUNTIF('اللبنانية'!H2:H119,"?") | G4: =B4-D4-E4-F4
A5: السورية (Syrian) | B5: 160 | C5: 94 | D5: =COUNTIF('السورية'!H2:H161,"✔") | E5: =COUNTIF('السورية'!H2:H161,"✖") | F5: =COUNTIF('السورية'!H2:H161,"?") | G5: =B5-D5-E5-F5
A6: الأردنية (Jordanian) | B6: 201 | C6: 136 | D6: =COUNTIF('الأردنية'!H2:H202,"✔") | E6: =COUNTIF('الأردنية'!H2:H202,"✖") | F6: =COUNTIF('الأردنية'!H2:H202,"?") | G6: =B6-D6-E6-F6
A7: المصرية (Egyptian) | B7: 121 | C7: 5 | D7: =COUNTIF('المصرية'!H2:H122,"✔") | E7: =COUNTIF('المصرية'!H2:H122,"✖") | F7: =COUNTIF('المصرية'!H2:H122,"?") | G7: =B7-D7-E7-F7
A8: الفصحى (Fusha) | B8: 129 | C8: 0 | D8: =COUNTIF('الفصحى'!H2:H130,"✔") | E8: =COUNTIF('الفصحى'!H2:H130,"✖") | F8: =COUNTIF('الفصحى'!H2:H130,"?") | G8: =B8-D8-E8-F8
A9: ردود حية (Live replies) | B9: 30 | C9: 0 | D9: =COUNTIF('ردود حية'!F2:F31,"✔") | E9: =COUNTIF('ردود حية'!F2:F31,"✖") | F9: =COUNTIF('ردود حية'!F2:F31,"?") | G9: =B9-D9-E9-F9
A10: السلامة (Safety) | B10: 49 | C10: 0 | D10: =COUNTIF('السلامة'!G3:G51,"✔") | E10: =COUNTIF('السلامة'!G3:G51,"✖") | F10: =COUNTIF('السلامة'!G3:G51,"?") | G10: =B10-D10-E10-F10
A11: قواعد - الشرح (Grammar: explanations) | B11: 620 | C11: 391 | D11: =COUNTIF('قواعد - الشرح'!I2:I621,"✔") | E11: =COUNTIF('قواعد - الشرح'!I2:I621,"✖") | F11: =COUNTIF('قواعد - الشرح'!I2:I621,"?") | G11: =B11-D11-E11-F11
A12: قواعد - الألعاب (Grammar: game items) | B12: 104 | C12: 34 | D12: =COUNTIF('قواعد - الألعاب'!K2:K105,"✔") | E12: =COUNTIF('قواعد - الألعاب'!K2:K105,"✖") | F12: =COUNTIF('قواعد - الألعاب'!K2:K105,"?") | G12: =B12-D12-E12-F12
A13: مشاهد المحادثة (v20 talk scenes) | B13: 430 | C13: 0 | D13: =COUNTIF('مشاهد المحادثة'!H2:H431,"✔") | E13: =COUNTIF('مشاهد المحادثة'!H2:H431,"✖") | F13: =COUNTIF('مشاهد المحادثة'!H2:H431,"?") | G13: =B13-D13-E13-F13
A14: النطق (Pronunciation tips + feedback) | B14: 114 | C14: 0 | D14: =COUNTIF('النطق'!G2:G115,"✔") | E14: =COUNTIF('النطق'!G2:G115,"✖") | F14: =COUNTIF('النطق'!G2:G115,"?") | G14: =B14-D14-E14-F14
A15: القراءة لصقور (Read-aloud feedback) | B15: 15 | C15: 0 | D15: =COUNTIF('القراءة لصقور'!F2:F16,"✔") | E15: =COUNTIF('القراءة لصقور'!F2:F16,"✖") | F15: =COUNTIF('القراءة لصقور'!F2:F16,"?") | G15: =B15-D15-E15-F15
A16: المراجعة (Review prompts) | B16: 24 | C16: 0 | D16: =COUNTIF('المراجعة'!G2:G25,"✔") | E16: =COUNTIF('المراجعة'!G2:G25,"✖") | F16: =COUNTIF('المراجعة'!G2:G25,"?") | G16: =B16-D16-E16-F16
A17: الدروس والجزر (Topic to island (grade band)) | B17: 16 | C17: 0 | D17: =COUNTIF('الدروس والجزر'!F2:F17,"✔") | E17: =COUNTIF('الدروس والجزر'!F2:F17,"✖") | F17: =COUNTIF('الدروس والجزر'!F2:F17,"?") | G17: =B17-D17-E17-F17
A18: المجموع (Total) | B18: =SUM(B2:B17) | C18: =SUM(C2:C17) | D18: =SUM(D2:D17) | E18: =SUM(E2:E17) | F18: =SUM(F2:F17) | G18: =SUM(G2:G17)

Sheet الإماراتية
A1: الرقم ID | B1: أين تظهر Where it appears | C1: ولد / بنت Boy / girl | D1: الجملة The line | E1: المعنى English meaning | F1: أولوية Priority | G1: سبب المراجعة Why flagged | H1: الحالة Status | I1: الجملة المصحّحة Corrected line | J1: ملاحظات المعلّم Teacher notes
A2: u13.d0 | B2: محتوى الدرس Lesson content | C2: للجميع both | D2: عَرِّفِينَا عَن نَفْسِج يَا نُورَة. | E2: Tell us about yourself, Noura. | F2: ★ | G2: review L: عرّفينا بنفسج is a Fusha calque; عن نفسج is natural
A3: u14.d1 | B3: محتوى الدرس Lesson content | C3: للجميع both | D3: رَاسِي يْعَوِّرْنِي وِأَنَا تَعْبَان. | E3: My head hurts and I'm tired. | F3: ★ | G3: review M: As u14.v4
A4: u14.v4 | B4: محتوى الدرس Lesson content | C4: للجميع both | D4: رَاسِي يْعَوِّرْنِي | E4: my head hurts | F4: ★ | G4: review M: Emirati kids say يعوّرني; يوجّعني is less common in UAE speech [S4,S8]
A5: u16.d0 | B5: محتوى الدرس Lesson content | C5: للجميع both | D5: شُو بِتْسَوِّين آخِر الأُسْبُوع؟ | E5: What will you do at the weekend? | F5: ★ | G5: review M: نهاية الأسبوع is Fusha phrasing; speech uses آخر الأسبوع / الويكند
A6: falcon.greet | B6: الصَّفْحَةُ الرَّئِيسِيَّةُ (صَقُّور) Falcon home | C6: ولد boy | D6: هَلَا {name}! شَحَالَك اليُوم؟ | E6: Hi {name}! How are you today?
A7: falcon.greet | B7: الصَّفْحَةُ الرَّئِيسِيَّةُ (صَقُّور) Falcon home | C7: بنت girl | D7: هَلَا {name}! شَحَالِج اليُوم؟ | E7: Hi {name}! How are you today?
A8: falcon.ai | B8: الصَّفْحَةُ الرَّئِيسِيَّةُ (صَقُّور) Falcon home | C8: للجميع both | D8: تَرَى أَنَا مُسَاعِد ذَكَاء اصْطِنَاعِي، مُب إِنْسَان. | E8: I'm an AI helper, not a person.
A9: falcon.sug_letter | B9: الصَّفْحَةُ الرَّئِيسِيَّةُ (صَقُّور) Falcon home | C9: ولد boy | D9: شُو رَايَك نِتْدَرَّب عَلَى هَالحَرْف؟ | E9: How about we practise this letter?
A10: falcon.sug_letter | B10: الصَّفْحَةُ الرَّئِيسِيَّةُ (صَقُّور) Falcon home | C10: بنت girl | D10: شُو رَايِج نِتْدَرَّب عَلَى هَالحَرْف؟ | E10: How about we practise this letter?
A11: falcon.sug_story | B11: الصَّفْحَةُ الرَّئِيسِيَّةُ (صَقُّور) Falcon home | C11: ولد boy | D11: وَلَّا تَبَا قِصَّة؟ | E11: Or do you want a story?
A12: falcon.sug_story | B12: الصَّفْحَةُ الرَّئِيسِيَّةُ (صَقُّور) Falcon home | C12: بنت girl | D12: وَلَّا تَبِين قِصَّة؟ | E12: Or do you want a story?
A13: falcon.sug_wordle | B13: الصَّفْحَةُ الرَّئِيسِيَّةُ (صَقُّور) Falcon home | C13: ولد boy | D13: كَلِمَة اليُوم تِنْطِرك! | E13: Today's word is waiting for you!
A14: falcon.sug_wordle | B14: الصَّفْحَةُ الرَّئِيسِيَّةُ (صَقُّور) Falcon home | C14: بنت girl | D14: كَلِمَة اليُوم تِنْطِرج! | E14: Today's word is waiting for you!
A15: falcon.sug_game | B15: الصَّفْحَةُ الرَّئِيسِيَّةُ (صَقُّور) Falcon home | C15: ولد boy | D15: تَبَا لُعْبَة سَرِيعَة؟ | E15: Want a quick game?
A16: falcon.sug_game | B16: الصَّفْحَةُ الرَّئِيسِيَّةُ (صَقُّور) Falcon home | C16: بنت girl | D16: تَبِين لُعْبَة سَرِيعَة؟ | E16: Want a quick game?
A17: falcon.sug_dress | B17: الصَّفْحَةُ الرَّئِيسِيَّةُ (صَقُّور) Falcon home | C17: ولد boy | D17: عِنْدِي لِبْس جِدِيد! تَبَا تْشُوفَه؟ | E17: I have something new to wear!
... A121: refuse.other | B121: رَفْضٌ لَطِيفٌ (مَعْلُومَات خَاصَّة / مَوْضُوع غَيْر مُنَاسِب) Gentle refusal (private info / unsuitable topic) | C121: للجميع both | D121: أَنَا بَسّ أَسَاعِد فِي العَرَبِي. يَلَّا نْكَمِّل الدَّرْس! | E121: I can only help with Arabic, so let's carry on with the lesson!

Sheet السعودية
A1: الرقم ID | B1: أين تظهر Where it appears | C1: ولد / بنت Boy / girl | D1: الجملة The line | E1: المعنى English meaning | F1: أولوية Priority | G1: سبب المراجعة Why flagged | H1: الحالة Status | I1: الجملة المصحّحة Corrected line | J1: ملاحظات المعلّم Teacher notes
A2: dd.saudi.2 | B2: محتوى الدرس Lesson content | C2: للجميع both | D2: وِش تَبِين تْسَوِّين الحِين؟ | F2: ★ | G2: Najdi أبي/تبي
A3: dd.saudi.3 | B3: محتوى الدرس Lesson content | C3: للجميع both | D3: أَبِي أَقْرَا قِصَّة، مَرَّة حِلْوَة! | F3: ★ | G3: Najdi أبي/تبي
A4: quiz.detective.3 | B4: محتوى الدرس Lesson content | C4: للجميع both | D4: وِش عُلُومَك؟ وِش تَبِي الحِين؟ | F4: ★ | G4: Najdi أبي/تبي
A5: quiz.fusha.0.3 | B5: محتوى الدرس Lesson content | C5: للجميع both | D5: وِش تَبِي؟ | F5: ★ | G5: Najdi أبي/تبي
A6: u1.d1 | B6: محتوى الدرس Lesson content | C6: للجميع both | D6: صَبَاح النُّور! شْلُونَك؟ | E6: Good morning! How are you? | F6: ★ | G6: review M: كيف حالك is near-Fusha; شلونك/كيفك are everyday Najdi
A7: u11.d0 | B7: محتوى الدرس Lesson content | C7: للجميع both | D7: لَو سَمَحْت، أَبِي عَصِير بُرْتُقَال. | E7: Excuse me, I'd like an orange juice. | F7: ★ | G7: Najdi أبي
A8: u11.d1 | B8: محتوى الدرس Lesson content | C8: للجميع both | D8: أَبْشِر. تَبِي شَي ثَانِي؟ | E8: Sure. Anything else? | F8: ★ | G8: Najdi تبي
A9: u11.v4 | B9: محتوى الدرس Lesson content | C9: للجميع both | D9: أَبِي | E9: I want | F9: ★ | G9: Najdi "I want" is أبي; أبغى is Hijazi
A10: u12.d1 | B10: محتوى الدرس Lesson content | C10: للجميع both | D10: بِنِلْبَس الثُّوب وَنِرْفَع العَلَم. | E10: We'll wear the kandura and raise the flag. | F10: ★ | G10: review M: Najdi future = بـ prefix (بنظّف/بجي); رَاح is Hijazi/Levantine. App is labelled Saudi but mixes Najdi + Hijazi [S2,S3,S12]
A11: u12.d2 | B11: محتوى الدرس Lesson content | C11: للجميع both | D11: وَأَنَا بَرْسِم عَلَم الإِمَارَات. | E11: And I'll draw the UAE flag. | F11: ★ | G11: review M: Najdi future = بـ prefix (بنظّف/بجي); رَاح is Hijazi/Levantine. App is labelled Saudi but mixes Najdi + Hijazi [S2,S3,S12]
A12: u13.d3 | B12: محتوى الدرس Lesson content | C12: للجميع both | D12: مُمْتَاز! وِش تَبِين تْصِيرِين إِذَا كِبَرْتِي؟ | E12: Excellent! What do you want to be when you grow up? | F12: ★ | G12: review L: لمّا is Hijazi/Levantine; Najdi uses إذا/يوم + past; تبين common in Riyadh
A13: u13.d4 | B13: محتوى الدرس Lesson content | C13: للجميع both | D13: أَبِي أَصِير دَكْتُورَة. | E13: I want to be a doctor. | F13: ★ | G13: Najdi أبي
A14: u14.d1 | B14: محتوى الدرس Lesson content | C14: للجميع both | D14: رَاسِي يْعَوِّرْنِي وَأَنَا تَعْبَان. | E14: My head hurts and I'm tired. | F14: ★ | G14: review M: As u14.v4
A15: u14.d2 | B15: محتوى الدرس Lesson content | C15: للجميع both | D15: لَازِم تِشْرَب مُوَيَّة وَتِرْتَاح. | E15: You should drink water and rest. | F15: ★ | G15: مويّة spelling, as in the u7.v1 correction
A16: u14.v4 | B16: محتوى الدرس Lesson content | C16: للجميع both | D16: رَاسِي يْعَوِّرْنِي | E16: my head hurts | F16: ★ | G16: review M: Gulf/Najdi kids say يعوّرني (it hurts me); يوجعني is fine but more formal-sounding
A17: u16.d0 | B17: محتوى الدرس Lesson content | C17: للجميع both | D17: وِش بِتْسَوِّين آخِر الأُسْبُوع؟ | E17: What will you do at the weekend? | F17: ★ | G17: review M: Najdi future = بـ prefix (بنظّف/بجي); رَاح is Hijazi/Levantine. App is labelled Saudi but mixes Najdi + Hijazi [S2,S3,S12]
... A25: u7.v1 | B25: محتوى الدرس Lesson content | C25: للجميع both | D25: مُوَيَّة | E25: water | F25: ★ | G25: review M: Spelling: Najdi مويّه/موية (muwayya); مُوِيَه has wrong vowels [S3]
A26: falcon.greet | B26: الصَّفْحَةُ الرَّئِيسِيَّةُ (صَقُّور) Falcon home | C26: ولد boy | D26: هَلَا {name}! كَيْفَك اليُوم؟ | E26: Hi {name}! How are you today?
A27: falcon.greet | B27: الصَّفْحَةُ الرَّئِيسِيَّةُ (صَقُّور) Falcon home | C27: بنت girl | D27: هَلَا {name}! كَيْفِك اليُوم؟ | E27: Hi {name}! How are you today?
A28: falcon.ai | B28: الصَّفْحَةُ الرَّئِيسِيَّةُ (صَقُّور) Falcon home | C28: للجميع both | D28: تَرَى أَنَا مُسَاعِد ذَكَاء اصْطِنَاعِي، مُو إِنْسَان. | E28: I'm an AI helper, not a person.
A29: falcon.sug_letter | B29: الصَّفْحَةُ الرَّئِيسِيَّةُ (صَقُّور) Falcon home | C29: ولد boy | D29: وِش رَايَك نِتْدَرَّب عَلَى هَالحَرْف؟ | E29: How about we practise this letter?
A30: falcon.sug_letter | B30: الصَّفْحَةُ الرَّئِيسِيَّةُ (صَقُّور) Falcon home | C30: بنت girl | D30: وِش رَايِك نِتْدَرَّب عَلَى هَالحَرْف؟ | E30: How about we practise this letter?
A31: falcon.sug_story | B31: الصَّفْحَةُ الرَّئِيسِيَّةُ (صَقُّور) Falcon home | C31: ولد boy | D31: وَلَّا تَبْغَى قِصَّة؟ | E31: Or do you want a story?
A32: falcon.sug_story | B32: الصَّفْحَةُ الرَّئِيسِيَّةُ (صَقُّور) Falcon home | C32: بنت girl | D32: وَلَّا تَبْغِين قِصَّة؟ | E32: Or do you want a story?
A33: falcon.sug_wordle | B33: الصَّفْحَةُ الرَّئِيسِيَّةُ (صَقُّور) Falcon home | C33: للجميع both | D33: كِلْمَة اليُوم تِنْتِظْرك! | E33: Today's word is waiting for you!
A34: falcon.sug_game | B34: الصَّفْحَةُ الرَّئِيسِيَّةُ (صَقُّور) Falcon home | C34: ولد boy | D34: تَبْغَى لُعْبَة سَرِيعَة؟ | E34: Want a quick game?
A35: falcon.sug_game | B35: الصَّفْحَةُ الرَّئِيسِيَّةُ (صَقُّور) Falcon home | C35: بنت girl | D35: تَبْغِين لُعْبَة سَرِيعَة؟ | E35: Want a quick game?
A36: falcon.sug_dress | B36: الصَّفْحَةُ الرَّئِيسِيَّةُ (صَقُّور) Falcon home | C36: ولد boy | D36: عِنْدِي لِبْس جْدِيد! تَبْغَى تْشُوفَه؟ | E36: I have something new to wear!
A37: falcon.sug_dress | B37: الصَّفْحَةُ الرَّئِيسِيَّةُ (صَقُّور) Falcon home | C37: بنت girl | D37: عِنْدِي لِبْس جْدِيد! تَبْغِين تْشُوفِينَه؟ | E37: I have something new to wear!
... A135: refuse.other | B135: رَفْضٌ لَطِيفٌ (مَعْلُومَات خَاصَّة / مَوْضُوع غَيْر مُنَاسِب) Gentle refusal (private info / unsuitable topic) | C135: للجميع both | D135: أَنَا بَسّ أَسَاعِد فِي العَرَبِي. يَلَّا نْكَمِّل الدَّرْس! | E135: I can only help with Arabic, so let's carry on with the lesson!

Sheet اللبنانية
A1: الرقم ID | B1: أين تظهر Where it appears | C1: ولد / بنت Boy / girl | D1: الجملة The line | E1: المعنى English meaning | F1: أولوية Priority | G1: سبب المراجعة Why flagged | H1: الحالة Status | I1: الجملة المصحّحة Corrected line | J1: ملاحظات المعلّم Teacher notes
A2: u13.v4 | B2: محتوى الدرس Lesson content | C2: للجميع both | D2: بْيِسْتِحِي | E2: shy | F2: ★ | G2: review L: خجول is Fusha-ish; Lebanese kids say بيستحي / خجلان
A3: u15.d3 | B3: محتوى الدرس Lesson content | C3: للجميع both | D3: كَان الجَوّ بَارِد؟ | E3: Was the weather cold? | F3: ★ | G3: الطقس is formal; everyday الجو (same fix as Jordanian)
A4: u7.d2 | B4: محتوى الدرس Lesson content | C4: للجميع both | D4: طَيِّب! وْبَدِّي مَيّ بَارْدِة. | E4: Great! And I want cold water. | F4: ★ | G4: review M: عظيم is formal/Fusha-ish as an exclamation; طيّب / منيح is natural
A5: u8.v1 | B5: محتوى الدرس Lesson content | C5: للجميع both | D5: المِسّ | E5: teacher (f) | F5: ★ | G5: review M: Levantine schoolchildren call the teacher المِسّ or الآنسة; معلّمة is correct but not what kids say
A6: falcon.greet | B6: الصَّفْحَةُ الرَّئِيسِيَّةُ (صَقُّور) Falcon home | C6: ولد boy | D6: مَرْحَبا {name}! كِيفَك اليُوم؟ | E6: Hi {name}! How are you today?
A7: falcon.greet | B7: الصَّفْحَةُ الرَّئِيسِيَّةُ (صَقُّور) Falcon home | C7: بنت girl | D7: مَرْحَبا {name}! كِيفِك اليُوم؟ | E7: Hi {name}! How are you today?
A8: falcon.ai | B8: الصَّفْحَةُ الرَّئِيسِيَّةُ (صَقُّور) Falcon home | C8: للجميع both | D8: عَلَى فِكْرَة أَنَا مْسَاعِد ذَكَاء اصْطِنَاعِي، مِش إِنْسَان. | E8: I'm an AI helper, not a person.
A9: falcon.sug_letter | B9: الصَّفْحَةُ الرَّئِيسِيَّةُ (صَقُّور) Falcon home | C9: ولد boy | D9: شُو رَأْيَك نِتْمَرَّن عَلَى هَالحَرْف؟ | E9: How about we practise this letter?
A10: falcon.sug_letter | B10: الصَّفْحَةُ الرَّئِيسِيَّةُ (صَقُّور) Falcon home | C10: بنت girl | D10: شُو رَأْيِك نِتْمَرَّن عَلَى هَالحَرْف؟ | E10: How about we practise this letter?
A11: falcon.sug_story | B11: الصَّفْحَةُ الرَّئِيسِيَّةُ (صَقُّور) Falcon home | C11: ولد boy | D11: وَلَّا بَدَّك قِصَّة؟ | E11: Or do you want a story?
A12: falcon.sug_story | B12: الصَّفْحَةُ الرَّئِيسِيَّةُ (صَقُّور) Falcon home | C12: بنت girl | D12: وَلَّا بَدِّك قِصَّة؟ | E12: Or do you want a story?
A13: falcon.sug_wordle | B13: الصَّفْحَةُ الرَّئِيسِيَّةُ (صَقُّور) Falcon home | C13: ولد boy | D13: كِلْمِة اليُوم عَم تِسْتَنَّاك! | E13: Today's word is waiting for you!
A14: falcon.sug_wordle | B14: الصَّفْحَةُ الرَّئِيسِيَّةُ (صَقُّور) Falcon home | C14: بنت girl | D14: كِلْمِة اليُوم عَم تِسْتَنَّاكِي! | E14: Today's word is waiting for you!
A15: falcon.sug_game | B15: الصَّفْحَةُ الرَّئِيسِيَّةُ (صَقُّور) Falcon home | C15: ولد boy | D15: بَدَّك لِعْبِة سَرِيعَة؟ | E15: Want a quick game?
A16: falcon.sug_game | B16: الصَّفْحَةُ الرَّئِيسِيَّةُ (صَقُّور) Falcon home | C16: بنت girl | D16: بَدِّك لِعْبِة سَرِيعَة؟ | E16: Want a quick game?
A17: falcon.sug_dress | B17: الصَّفْحَةُ الرَّئِيسِيَّةُ (صَقُّور) Falcon home | C17: ولد boy | D17: عِنْدِي تْيَاب جْدِيدِة! بَدَّك تْشُوفُن؟ | E17: I have something new to wear!
... A119: refuse.other | B119: رَفْضٌ لَطِيفٌ (مَعْلُومَات خَاصَّة / مَوْضُوع غَيْر مُنَاسِب) Gentle refusal (private info / unsuitable topic) | C119: للجميع both | D119: أَنَا بْسَاعِد بَسّ بِالعَرَبِي. يَلَّا نْكَمِّل الدَّرْس! | E119: I can only help with Arabic, so let's carry on with the lesson!

Sheet السورية
A1: الرقم ID | B1: أين تظهر Where it appears | C1: ولد / بنت Boy / girl | D1: الجملة The line | E1: المعنى English meaning | F1: أولوية Priority | G1: سبب المراجعة Why flagged | H1: الحالة Status | I1: الجملة المصحّحة Corrected line | J1: ملاحظات المعلّم Teacher notes
A2: falcon.greet | B2: الصَّفْحَةُ الرَّئِيسِيَّةُ (صَقُّور) Falcon home | C2: ولد boy | D2: أَهْلِين {name}! شْلُونَك اليُوم؟ | E2: Hi {name}! How are you today? | F2: ★ | G2: new v16 falcon-home line, written from the Levantine guidance (not native-checked)
A3: falcon.greet | B3: الصَّفْحَةُ الرَّئِيسِيَّةُ (صَقُّور) Falcon home | C3: بنت girl | D3: أَهْلِين {name}! شْلُونِك اليُوم؟ | E3: Hi {name}! How are you today? | F3: ★ | G3: new v16 falcon-home line, written from the Levantine guidance (not native-checked)
A4: falcon.ai | B4: الصَّفْحَةُ الرَّئِيسِيَّةُ (صَقُّور) Falcon home | C4: للجميع both | D4: عَلَى فِكْرَة أَنَا مْسَاعِد ذَكَاء اصْطِنَاعِي، مُو إِنْسَان. | E4: I'm an AI helper, not a person. | F4: ★ | G4: new v16 falcon-home line, written from the Levantine guidance (not native-checked)
A5: falcon.sug_letter | B5: الصَّفْحَةُ الرَّئِيسِيَّةُ (صَقُّور) Falcon home | C5: ولد boy | D5: شُو بْتْقُول نِتْدَرَّب عَلَى هَالحَرْف شْوَي؟ | E5: How about we practise this letter? | F5: ★ | G5: new v16 falcon-home line, written from the Levantine guidance (not native-checked)
A6: falcon.sug_letter | B6: الصَّفْحَةُ الرَّئِيسِيَّةُ (صَقُّور) Falcon home | C6: بنت girl | D6: شُو بْتْقُولِي نِتْدَرَّب عَلَى هَالحَرْف شْوَي؟ | E6: How about we practise this letter? | F6: ★ | G6: new v16 falcon-home line, written from the Levantine guidance (not native-checked)
A7: falcon.sug_story | B7: الصَّفْحَةُ الرَّئِيسِيَّةُ (صَقُّور) Falcon home | C7: ولد boy | D7: وَلَّا بَدَّك قِصَّة حِلْوِة؟ | E7: Or do you want a story? | F7: ★ | G7: new v16 falcon-home line, written from the Levantine guidance (not native-checked)
A8: falcon.sug_story | B8: الصَّفْحَةُ الرَّئِيسِيَّةُ (صَقُّور) Falcon home | C8: بنت girl | D8: وَلَّا بَدِّك قِصَّة حِلْوِة؟ | E8: Or do you want a story? | F8: ★ | G8: new v16 falcon-home line, written from the Levantine guidance (not native-checked)
A9: falcon.sug_wordle | B9: الصَّفْحَةُ الرَّئِيسِيَّةُ (صَقُّور) Falcon home | C9: ولد boy | D9: كِلْمِة اليُوم نَاطْرْتَك! | E9: Today's word is waiting for you! | F9: ★ | G9: new v16 falcon-home line, written from the Levantine guidance (not native-checked)
A10: falcon.sug_wordle | B10: الصَّفْحَةُ الرَّئِيسِيَّةُ (صَقُّور) Falcon home | C10: بنت girl | D10: كِلْمِة اليُوم نَاطْرْتِك! | E10: Today's word is waiting for you! | F10: ★ | G10: new v16 falcon-home line, written from the Levantine guidance (not native-checked)
A11: falcon.sug_game | B11: الصَّفْحَةُ الرَّئِيسِيَّةُ (صَقُّور) Falcon home | C11: ولد boy | D11: بَدَّك لِعْبِة سَرِيعَة هَلَّأ؟ | E11: Want a quick game? | F11: ★ | G11: new v16 falcon-home line, written from the Levantine guidance (not native-checked)
A12: falcon.sug_game | B12: الصَّفْحَةُ الرَّئِيسِيَّةُ (صَقُّور) Falcon home | C12: بنت girl | D12: بَدِّك لِعْبِة سَرِيعَة هَلَّأ؟ | E12: Want a quick game? | F12: ★ | G12: new v16 falcon-home line, written from the Levantine guidance (not native-checked)
A13: falcon.sug_dress | B13: الصَّفْحَةُ الرَّئِيسِيَّةُ (صَقُّور) Falcon home | C13: ولد boy | D13: عِنْدِي تْيَاب جْدَاد! بَدَّك تْشُوفُن؟ | E13: I have something new to wear! | F13: ★ | G13: new v16 falcon-home line, written from the Levantine guidance (not native-checked)
... A95: falcon-v16.win | B95: الصفحة الرئيسية (صقّور) Falcon home | C95: بنت girl | D95: يِسْلَمُوا إِيدَيْكِي! كْتِير شَاطْرَة! / بْرَافُو عَلَيْكِي! عْمِلْتِيهَا! | E95: Brilliant! You did it! | F95: ★ | G95: new v16 falcon-home line, written from the Levantine guidance (not native-checked)
A96: falcon.win.1 | B96: الصَّفْحَةُ الرَّئِيسِيَّةُ (صَقُّور) Falcon home | C96: ولد boy | D96: يِسْلَمُوا إِيدَيْك! كْتِير شَاطِر! | E96: Brilliant! You did it!
A97: falcon.win.1 | B97: الصَّفْحَةُ الرَّئِيسِيَّةُ (صَقُّور) Falcon home | C97: بنت girl | D97: يِسْلَمُوا إِيدَيْكِي! كْتِير شَاطْرَة! | E97: Brilliant! You did it!
A98: falcon.win.2 | B98: الصَّفْحَةُ الرَّئِيسِيَّةُ (صَقُّور) Falcon home | C98: ولد boy | D98: بْرَافُو عَلَيْك! عْمِلْتَهَا! | E98: Brilliant! You did it!
A99: falcon.win.2 | B99: الصَّفْحَةُ الرَّئِيسِيَّةُ (صَقُّور) Falcon home | C99: بنت girl | D99: بْرَافُو عَلَيْكِي! عْمِلْتِيهَا! | E99: Brilliant! You did it!
A100: lesson.intro | B100: الدَّرْسُ مَعَ صَقُّور Lesson with Saqqour | C100: للجميع both | D100: مَرْحَبا {name}! أَنَا صَقُّور، المْسَاعِد الذَّكِي تَبَعك. أَنَا ذَكَاء اصْطِنَاعِي، مِش إِنْسَان. يَلَّا نِتْعَلَّم عَرَبِي! | E100: Hi {name}! I'm Saqqour, your AI tutor. I'm a computer helper, not a person. Let's learn Arabic together!
A101: lesson.greet | B101: الدَّرْسُ مَعَ صَقُّور Lesson with Saqqour | C101: ولد boy | D101: مَرْحَبا {name}! كِيفَك اليُوم؟ | E101: Hi {name}! How are you today?
A102: lesson.greet | B102: الدَّرْسُ مَعَ صَقُّور Lesson with Saqqour | C102: بنت girl | D102: مَرْحَبا {name}! كِيفِك اليُوم؟ | E102: Hi {name}! How are you today?
A103: lesson.mood_good | B103: الدَّرْسُ مَعَ صَقُّور Lesson with Saqqour | C103: للجميع both | D103: كْتِير مْنِيح! يَلَّا نِبْلُش. | E103: Great! Then let's go.
A104: lesson.mood_tired | B104: الدَّرْسُ مَعَ صَقُّور Lesson with Saqqour | C104: للجميع both | D104: مَا في مُشْكِلِة، رَح نَعْمِل شِي خَفِيف وْقَصِير. | E104: That's okay. We'll do something short and easy today.
A105: lesson.mood_excited | B105: الدَّرْسُ مَعَ صَقُّور Lesson with Saqqour | C105: للجميع both | D105: يِسْلَمُو! بْحِبّ هَالحَمَاس. يَلَّا! | E105: Yay! I love that energy. Let's go!
A106: lesson.plan | B106: الدَّرْسُ مَعَ صَقُّور Lesson with Saqqour | C106: للجميع both | D106: اليُوم رَح نْقَوِّي {skill}. | E106: Today's power-up is . I picked it from your practice.
A107: lesson.review | B107: الدَّرْسُ مَعَ صَقُّور Lesson with Saqqour | C107: ولد boy | D107: مِتْذَكِّر هَالكِلْمِة؟ كَانِت صَعْبِة شْوَي. | E107: Remember this word? It was a bit tricky last time.
... A161: refuse.other | B161: رَفْضٌ لَطِيفٌ (مَعْلُومَات خَاصَّة / مَوْضُوع غَيْر مُنَاسِب) Gentle refusal (private info / unsuitable topic) | C161: للجميع both | D161: أَنَا بْسَاعِد بَسّ بِالعَرَبِي. يَلَّا نْكَمِّل الدَّرْس! | E161: I can only help with Arabic, so let's carry on with the lesson!

Sheet الأردنية
A1: الرقم ID | B1: أين تظهر Where it appears | C1: ولد / بنت Boy / girl | D1: الجملة The line | E1: المعنى English meaning | F1: أولوية Priority | G1: سبب المراجعة Why flagged | H1: الحالة Status | I1: الجملة المصحّحة Corrected line | J1: ملاحظات المعلّم Teacher notes
A2: falcon.greet | B2: الصَّفْحَةُ الرَّئِيسِيَّةُ (صَقُّور) Falcon home | C2: ولد boy | D2: هَلَا {name}! كِيفَك اليُوم؟ إِنْ شَاء الله مْنِيح؟ | E2: Hi {name}! How are you today? | F2: ★ | G2: new v16 falcon-home line, written from the Levantine guidance (not native-checked)
A3: falcon.greet | B3: الصَّفْحَةُ الرَّئِيسِيَّةُ (صَقُّور) Falcon home | C3: بنت girl | D3: هَلَا {name}! كِيفِك اليُوم؟ إِنْ شَاء الله مْنِيحَة؟ | E3: Hi {name}! How are you today? | F3: ★ | G3: new v16 falcon-home line, written from the Levantine guidance (not native-checked)
A4: falcon.ai | B4: الصَّفْحَةُ الرَّئِيسِيَّةُ (صَقُّور) Falcon home | C4: للجميع both | D4: عَلَى فِكْرَة أَنَا مُسَاعِد ذَكَاء اصْطِنَاعِي، مِش إِنْسَان. | E4: I'm an AI helper, not a person. | F4: ★ | G4: new v16 falcon-home line, written from the Levantine guidance (not native-checked)
A5: falcon.sug_letter | B5: الصَّفْحَةُ الرَّئِيسِيَّةُ (صَقُّور) Falcon home | C5: ولد boy | D5: شُو رَأْيَك نِتْدَرَّب عَلَى هَالحَرْف هَسَّا؟ | E5: How about we practise this letter? | F5: ★ | G5: new v16 falcon-home line, written from the Levantine guidance (not native-checked)
A6: falcon.sug_letter | B6: الصَّفْحَةُ الرَّئِيسِيَّةُ (صَقُّور) Falcon home | C6: بنت girl | D6: شُو رَأْيِك نِتْدَرَّب عَلَى هَالحَرْف هَسَّا؟ | E6: How about we practise this letter? | F6: ★ | G6: new v16 falcon-home line, written from the Levantine guidance (not native-checked)
A7: falcon.sug_story | B7: الصَّفْحَةُ الرَّئِيسِيَّةُ (صَقُّور) Falcon home | C7: ولد boy | D7: وَلَّا بِدَّك قِصَّة؟ | E7: Or do you want a story? | F7: ★ | G7: new v16 falcon-home line, written from the Levantine guidance (not native-checked)
A8: falcon.sug_story | B8: الصَّفْحَةُ الرَّئِيسِيَّةُ (صَقُّور) Falcon home | C8: بنت girl | D8: وَلَّا بِدِّك قِصَّة؟ | E8: Or do you want a story? | F8: ★ | G8: new v16 falcon-home line, written from the Levantine guidance (not native-checked)
A9: falcon.sug_wordle | B9: الصَّفْحَةُ الرَّئِيسِيَّةُ (صَقُّور) Falcon home | C9: ولد boy | D9: كَلِمِة اليُوم مِسْتَنِّيتَك! | E9: Today's word is waiting for you! | F9: ★ | G9: new v16 falcon-home line, written from the Levantine guidance (not native-checked)
A10: falcon.sug_wordle | B10: الصَّفْحَةُ الرَّئِيسِيَّةُ (صَقُّور) Falcon home | C10: بنت girl | D10: كَلِمِة اليُوم مِسْتَنِّيتِك! | E10: Today's word is waiting for you! | F10: ★ | G10: new v16 falcon-home line, written from the Levantine guidance (not native-checked)
A11: falcon.sug_game | B11: الصَّفْحَةُ الرَّئِيسِيَّةُ (صَقُّور) Falcon home | C11: ولد boy | D11: بِدَّك لُعْبِة سَرِيعَة؟ | E11: Want a quick game? | F11: ★ | G11: new v16 falcon-home line, written from the Levantine guidance (not native-checked)
A12: falcon.sug_game | B12: الصَّفْحَةُ الرَّئِيسِيَّةُ (صَقُّور) Falcon home | C12: بنت girl | D12: بِدِّك لُعْبِة سَرِيعَة؟ | E12: Want a quick game? | F12: ★ | G12: new v16 falcon-home line, written from the Levantine guidance (not native-checked)
A13: falcon.sug_dress | B13: الصَّفْحَةُ الرَّئِيسِيَّةُ (صَقُّور) Falcon home | C13: ولد boy | D13: عِنْدِي إِشِي جْدِيد أَلْبْسُه! بِدَّك تْشُوفُه؟ | E13: I have something new to wear! | F13: ★ | G13: new v16 falcon-home line, written from the Levantine guidance (not native-checked)
... A137: falcon-v16.win | B137: الصفحة الرئيسية (صقّور) Falcon home | C137: بنت girl | D137: يَا سَلَام! كْثِير شَاطْرَة! / عَاش! عْمِلْتِيهَا! | E137: Brilliant! You did it! | F137: ★ | G137: new v16 falcon-home line, written from the Levantine guidance (not native-checked)
A138: falcon.win.1 | B138: الصَّفْحَةُ الرَّئِيسِيَّةُ (صَقُّور) Falcon home | C138: ولد boy | D138: يَا سَلَام! كْثِير شَاطِر! | E138: Brilliant! You did it!
A139: falcon.win.1 | B139: الصَّفْحَةُ الرَّئِيسِيَّةُ (صَقُّور) Falcon home | C139: بنت girl | D139: يَا سَلَام! كْثِير شَاطْرَة! | E139: Brilliant! You did it!
A140: falcon.win.2 | B140: الصَّفْحَةُ الرَّئِيسِيَّةُ (صَقُّور) Falcon home | C140: ولد boy | D140: عَاش! عْمِلْتْهَا! | E140: Brilliant! You did it!
A141: falcon.win.2 | B141: الصَّفْحَةُ الرَّئِيسِيَّةُ (صَقُّور) Falcon home | C141: بنت girl | D141: عَاش! عْمِلْتِيهَا! | E141: Brilliant! You did it!
A142: lesson.intro | B142: الدَّرْسُ مَعَ صَقُّور Lesson with Saqqour | C142: للجميع both | D142: مَرْحَبا {name}! أَنَا صَقُّور، المْسَاعِد الذَّكِي تَبَعك. أَنَا ذَكَاء اصْطِنَاعِي، مِش إِنْسَان. يَلَّا نِتْعَلَّم عَرَبِي! | E142: Hi {name}! I'm Saqqour, your AI tutor. I'm a computer helper, not a person. Let's learn Arabic together!
A143: lesson.greet | B143: الدَّرْسُ مَعَ صَقُّور Lesson with Saqqour | C143: ولد boy | D143: مَرْحَبا {name}! كِيفَك اليُوم؟ | E143: Hi {name}! How are you today?
A144: lesson.greet | B144: الدَّرْسُ مَعَ صَقُّور Lesson with Saqqour | C144: بنت girl | D144: مَرْحَبا {name}! كِيفِك اليُوم؟ | E144: Hi {name}! How are you today?
A145: lesson.mood_good | B145: الدَّرْسُ مَعَ صَقُّور Lesson with Saqqour | C145: للجميع both | D145: كْتِير مْنِيح! يَلَّا نِبْلُش. | E145: Great! Then let's go.
A146: lesson.mood_tired | B146: الدَّرْسُ مَعَ صَقُّور Lesson with Saqqour | C146: للجميع both | D146: مَا في مُشْكِلِة، رَح نَعْمِل شِي خَفِيف وْقَصِير. | E146: That's okay. We'll do something short and easy today.
A147: lesson.mood_excited | B147: الدَّرْسُ مَعَ صَقُّور Lesson with Saqqour | C147: للجميع both | D147: يِسْلَمُو! بْحِبّ هَالحَمَاس. يَلَّا! | E147: Yay! I love that energy. Let's go!
A148: lesson.plan | B148: الدَّرْسُ مَعَ صَقُّور Lesson with Saqqour | C148: للجميع both | D148: اليُوم رَح نْقَوِّي {skill}. | E148: Today's power-up is . I picked it from your practice.
A149: lesson.review | B149: الدَّرْسُ مَعَ صَقُّور Lesson with Saqqour | C149: ولد boy | D149: مِتْذَكِّر هَالكِلْمِة؟ كَانِت صَعْبِة شْوَي. | E149: Remember this word? It was a bit tricky last time.
... A202: refuse.other | B202: رَفْضٌ لَطِيفٌ (مَعْلُومَات خَاصَّة / مَوْضُوع غَيْر مُنَاسِب) Gentle refusal (private info / unsuitable topic) | C202: للجميع both | D202: أَنَا بَسَاعِد بَسّ بِالعَرَبِي. يَلَّا نْكَمِّل الدَّرْس! | E202: I can only help with Arabic, so let's carry on with the lesson!

Sheet المصرية
A1: الرقم ID | B1: أين تظهر Where it appears | C1: ولد / بنت Boy / girl | D1: الجملة The line | E1: المعنى English meaning | F1: أولوية Priority | G1: سبب المراجعة Why flagged | H1: الحالة Status | I1: الجملة المصحّحة Corrected line | J1: ملاحظات المعلّم Teacher notes
A2: u12.d3 | B2: محتوى الدرس Lesson content | C2: للجميع both | D2: كُلّ سَنَة وِالإِمَارَات بِخِير! | E2: Happy National Day, UAE! | F2: ★ | G2: review M: طيّبين is for people (كل سنة وإنتو طيبين); a country takes بخير
A3: u13.d0 | B3: محتوى الدرس Lesson content | C3: للجميع both | D3: قُولِيلْنَا عَن نَفْسِك يَا نُورَا. | E3: Tell us about yourself, Noura. | F3: ★ | G3: عرّفينا بنفسك is a Fusha calque (same issue as Emirati u13.d0)
A4: u14.d1 | B4: محتوى الدرس Lesson content | C4: للجميع both | D4: رَاسِي بِتْوَجَعْنِي وَأَنَا تَعْبَان. | E4: My head hurts and I'm tired. | F4: ★ | G4: review M: As u14.v4
A5: u14.v4 | B5: محتوى الدرس Lesson content | C5: للجميع both | D5: رَاسِي بِتْوَجَعْنِي | E5: my head hurts | F5: ★ | G5: review M: راسي وجعاني is not idiomatic; Egyptians say راسي/دماغي بتوجعني or عندي صداع [S7]
A6: u9.d2 | B6: محتوى الدرس Lesson content | C6: للجميع both | D6: يَا خَبَر! أَنَا اتْأَخَّرْت! | E6: Oh no, I'm late! | F6: ★ | G6: review M: “يا نهار!” alone is incomplete; kids say يا خبر! / يا نهار أبيض!
A7: falcon.greet | B7: الصَّفْحَةُ الرَّئِيسِيَّةُ (صَقُّور) Falcon home | C7: ولد boy | D7: أَهْلاً يَا {name}! إِزَّيَّك النَّهَارْدَه؟ | E7: Hi {name}! How are you today?
A8: falcon.greet | B8: الصَّفْحَةُ الرَّئِيسِيَّةُ (صَقُّور) Falcon home | C8: بنت girl | D8: أَهْلاً يَا {name}! إِزَّيِّك النَّهَارْدَه؟ | E8: Hi {name}! How are you today?
A9: falcon.ai | B9: الصَّفْحَةُ الرَّئِيسِيَّةُ (صَقُّور) Falcon home | C9: للجميع both | D9: عَلَى فِكْرَة أَنَا مُسَاعِد ذَكَاء اصْطِنَاعِي، مِش بَنِي آدَم. | E9: I'm an AI helper, not a person.
A10: falcon.sug_letter | B10: الصَّفْحَةُ الرَّئِيسِيَّةُ (صَقُّور) Falcon home | C10: ولد boy | D10: إِيه رَأْيَك نِتْمَرَّن عَلَى الحَرْف دَه؟ | E10: How about we practise this letter?
A11: falcon.sug_letter | B11: الصَّفْحَةُ الرَّئِيسِيَّةُ (صَقُّور) Falcon home | C11: بنت girl | D11: إِيه رَأْيِك نِتْمَرَّن عَلَى الحَرْف دَه؟ | E11: How about we practise this letter?
A12: falcon.sug_story | B12: الصَّفْحَةُ الرَّئِيسِيَّةُ (صَقُّور) Falcon home | C12: ولد boy | D12: وَلَّا عَايِز حِكَايَة؟ | E12: Or do you want a story?
A13: falcon.sug_story | B13: الصَّفْحَةُ الرَّئِيسِيَّةُ (صَقُّور) Falcon home | C13: بنت girl | D13: وَلَّا عَايْزَة حِكَايَة؟ | E13: Or do you want a story?
A14: falcon.sug_wordle | B14: الصَّفْحَةُ الرَّئِيسِيَّةُ (صَقُّور) Falcon home | C14: ولد boy | D14: كِلْمِة النَّهَارْدَه مِسْتَنِّيَاك! | E14: Today's word is waiting for you!
A15: falcon.sug_wordle | B15: الصَّفْحَةُ الرَّئِيسِيَّةُ (صَقُّور) Falcon home | C15: بنت girl | D15: كِلْمِة النَّهَارْدَه مِسْتَنِّيَاكِي! | E15: Today's word is waiting for you!
A16: falcon.sug_game | B16: الصَّفْحَةُ الرَّئِيسِيَّةُ (صَقُّور) Falcon home | C16: ولد boy | D16: عَايِز لُعْبَة سَرِيعَة؟ | E16: Want a quick game?
A17: falcon.sug_game | B17: الصَّفْحَةُ الرَّئِيسِيَّةُ (صَقُّور) Falcon home | C17: بنت girl | D17: عَايْزَة لُعْبَة سَرِيعَة؟ | E17: Want a quick game?
A18: falcon.sug_dress | B18: الصَّفْحَةُ الرَّئِيسِيَّةُ (صَقُّور) Falcon home | C18: ولد boy | D18: عَنْدِي لِبْس جِدِيد! عَايِز تْشُوفُه؟ | E18: I have something new to wear!
... A122: refuse.other | B122: رَفْضٌ لَطِيفٌ (مَعْلُومَات خَاصَّة / مَوْضُوع غَيْر مُنَاسِب) Gentle refusal (private info / unsuitable topic) | C122: للجميع both | D122: أَنَا بَسَاعِد فِي العَرَبِي بَسّ. يَلَّا نْكَمِّل الدَّرْس! | E122: I can only help with Arabic, so let's carry on with the lesson!

Sheet الفصحى
A1: الرقم ID | B1: أين تظهر Where it appears | C1: ولد / بنت Boy / girl | D1: الجملة The line | E1: المعنى English meaning | F1: أولوية Priority | G1: سبب المراجعة Why flagged | H1: الحالة Status | I1: الجملة المصحّحة Corrected line | J1: ملاحظات المعلّم Teacher notes
A2: falcon.greet | B2: الصَّفْحَةُ الرَّئِيسِيَّةُ (صَقُّور) Falcon home | C2: ولد boy | D2: مَرْحَباً يَا {name}! كَيْفَ حَالُكَ اليَوْمَ؟ | E2: Hi {name}! How are you today?
A3: falcon.greet | B3: الصَّفْحَةُ الرَّئِيسِيَّةُ (صَقُّور) Falcon home | C3: بنت girl | D3: مَرْحَباً يَا {name}! كَيْفَ حَالُكِ اليَوْمَ؟ | E3: Hi {name}! How are you today?
A4: falcon.ai | B4: الصَّفْحَةُ الرَّئِيسِيَّةُ (صَقُّور) Falcon home | C4: للجميع both | D4: أَنَا مُسَاعِدُ ذَكَاءٍ اصْطِنَاعِيٍّ، وَلَسْتُ إِنْسَاناً. | E4: I'm an AI helper, not a person.
A5: falcon.sug_letter | B5: الصَّفْحَةُ الرَّئِيسِيَّةُ (صَقُّور) Falcon home | C5: ولد boy | D5: مَا رَأْيُكَ أَنْ نَتَدَرَّبَ عَلَى هَذَا الحَرْفِ؟ | E5: How about we practise this letter?
A6: falcon.sug_letter | B6: الصَّفْحَةُ الرَّئِيسِيَّةُ (صَقُّور) Falcon home | C6: بنت girl | D6: مَا رَأْيُكِ أَنْ نَتَدَرَّبَ عَلَى هَذَا الحَرْفِ؟ | E6: How about we practise this letter?
A7: falcon.sug_story | B7: الصَّفْحَةُ الرَّئِيسِيَّةُ (صَقُّور) Falcon home | C7: ولد boy | D7: أَمْ تُرِيدُ قِصَّةً؟ | E7: Or do you want a story?
A8: falcon.sug_story | B8: الصَّفْحَةُ الرَّئِيسِيَّةُ (صَقُّور) Falcon home | C8: بنت girl | D8: أَمْ تُرِيدِينَ قِصَّةً؟ | E8: Or do you want a story?
A9: falcon.sug_wordle | B9: الصَّفْحَةُ الرَّئِيسِيَّةُ (صَقُّور) Falcon home | C9: ولد boy | D9: كَلِمَةُ اليَوْمِ تَنْتَظِرُكَ! | E9: Today's word is waiting for you!
A10: falcon.sug_wordle | B10: الصَّفْحَةُ الرَّئِيسِيَّةُ (صَقُّور) Falcon home | C10: بنت girl | D10: كَلِمَةُ اليَوْمِ تَنْتَظِرُكِ! | E10: Today's word is waiting for you!
A11: falcon.sug_game | B11: الصَّفْحَةُ الرَّئِيسِيَّةُ (صَقُّور) Falcon home | C11: ولد boy | D11: هَلْ تُرِيدُ لُعْبَةً سَرِيعَةً؟ | E11: Want a quick game?
A12: falcon.sug_game | B12: الصَّفْحَةُ الرَّئِيسِيَّةُ (صَقُّور) Falcon home | C12: بنت girl | D12: هَلْ تُرِيدِينَ لُعْبَةً سَرِيعَةً؟ | E12: Want a quick game?
A13: falcon.sug_dress | B13: الصَّفْحَةُ الرَّئِيسِيَّةُ (صَقُّور) Falcon home | C13: ولد boy | D13: عِنْدِي لِبَاسٌ جَدِيدٌ! هَلْ تُرِيدُ أَنْ تَرَاهُ؟ | E13: I have something new to wear!
... A130: refuse.other | B130: رَفْضٌ لَطِيفٌ (مَعْلُومَات خَاصَّة / مَوْضُوع غَيْر مُنَاسِب) Gentle refusal (private info / unsuitable topic) | C130: للجميع both | D130: أَنَا أُسَاعِدُ فِي العَرَبِيَّةِ فَقَطْ. هَيَّا نُكْمِلُ الدَّرْسَ! | E130: I can only help with Arabic, so let's carry on with the lesson!

Sheet ردود حية
A1: الرقم ID | B1: اللهجة Dialect | C1: رسالة الطفل Child's message | D1: ردّ صقّور Saqqour's reply | E1: المعنى English meaning | F1: الحالة Status | G1: الجملة المصحّحة Corrected line | H1: ملاحظات المعلّم Teacher notes
A2: hw-wr-em-1 | B2: الإماراتية Emirati | C2: الحديقة، المدرسة، البحر — الواجب / task: امْلَأِ الفَرَاغَ بِالكَلِمَةِ المُنَاسِبَةِ (المَدْرَسَةِ ـ البَحْرِ ـ الحَدِيقَةِ): 1. ذَهَبَ الوَلَدُ إِلَى ____ لِيَتَعَلَّمَ. 2. يَسْبَحُ السَّمَكُ فِي ___ | D2: • (لهجة) حِلْوَة المُحَاوَلَة! خَلْنَا نْشُوفْهَا مَرَّة ثَانْيَة. • (فصحى) نَظَرْتُ إِلَى إجَابَاتِكِ. الكَلِمَةُ الأُولَى لا تُطَابِقُ مَكَانَ التَّعَلُّمِ لِلْوَلَدِ. الكَلِمَةُ الثَّانِيَةُ لا تُوَصِفُ مَوْقِعَ سِبَاحَةِ السَّمَكِ. الكَلِمَةُ الثَّالِثَةُ لا تُوَافِقُ المَكَانَ الَّذِي نَلْعَبُ فِيهِ بِالكُرَةِ • (لهجة) تُبِين تُصَحِّحِين التَّرْتِيب؟ جَرِّبِي تَحُطِّي كُلّ كَلِمَة فِي مَكَانْهَا! | E2: • Nice try! Let's look at it again. • I looked at your answers. The first word does not match the place a boy goes to learn. The second word does not describe where a fish swims. The third word does not match the place we play with a ball. • Will you correct the order? Try putting each word in its place!
A3: hw-fl-sa-1 | B3: السعودية Saudi | C3: وش المطلوب هنا؟ — الواجب / task: امْلَأِ الفَرَاغَ بِالكَلِمَةِ المُنَاسِبَةِ (المَدْرَسَةِ ـ البَحْرِ ـ الحَدِيقَةِ): 1. ذَهَبَ الوَلَدُ إِلَى ____ لِيَتَعَلَّمَ. 2. يَسْبَحُ السَّمَكُ فِي ___ | D3: • (لهجة) هَلَا وَالله! طَيِّبَة؟ نِبْدَا نَقْرَى السُّؤَال سَبَعِة. • (فصحى) المَطْلُوبُ: أَمْلَأُ كُلَّ فَرَاغٍ بِواحدةٍ مِنَ الثَّلَاثِ الْمُعْطَاةِ. • (فصحى) اقْرَأِ الجُمْلَةَ وَفَكِّرْ أَيْنَ يَحْدُثُ الفِعْلُ؛ اِخْتَرِ الْمَوْضِعَ الْمُلَائِمَ. • (لهجة) تَبِين أَبْدَا بأي جُمْلَة؟ جَرِّب تْعَبِّي الأَوَّلَة وَقُولِي. | E3: • Hello! Are you okay? Let's start reading the question together. • The task: fill each blank with one of the three given words. • Read the sentence and think where the action happens; choose the appropriate place. • Do you want to start with a sentence? Try filling the first one and tell me.
A4: hw-ok-jo-1 | B4: الأردنية Jordanian | C4: ما جمع كلمة كتاب؟ | D4: • (فصحى) المَطْلُوبُ: تَكْتُبُ جَمْعَ الكَلِمَةِ «كِتَاب». • (فصحى) قَواعِدُ الجَمْعِ تَقْسِمُ الأَسْمَاءَ: جَمْعٌ سَالِمٌ وَجَمْعٌ تَكْسِيرِيٌّ. فَكِّرْ أَيّ نَوْعٍ هِيَ «كِتَاب». • (لهجة) يَلَّا جَرِّب هَسَّا، شُو كَتَبْت؟ | E4: • The task: write the plural of the word 'book'. • Grammar: plurals are regular or broken. Think which kind 'kitāb' is. • Try it and tell me what you wrote.
A5: hw-ph-sy-1 | B5: السورية Syrian | C5: ساعدني بهي الوظيفة — (مع صورة ورقة عمل / with a worksheet photo) | D5: • (لهجة) أَهْلِين! شْلُونِك؟ يَلَّا نْشُوف الوَرَقة سَوّا. • (فصحى) المَطْلُوبُ: كِتَابَةُ جَمْعِ الثَّلاثِ كَلِماتٍ المُعْطَاةِ. • (فصحى) هَذِهِِ التَّمْرِينَاتُ تَتَدَرَّبُ عَلَى جَمْعِ الأَسْمَاءِ. بَعْضُ الجُمُوعِ مُنْظَمَةٌ وَبَعْضُها مُنْكَسِرٌ. • (لهجة) هَلَّأ تْحِبِّي تِجَرِّبِي تِكْتِبِي جَمْع كلمة وَاحِدِة؟ | E5: • Hi! How are you? Let's look at the sheet together. • The task: write the plural of the three given words. • These exercises practice forming plurals. Some plurals are regular and some are broken. • Now would you like to try writing the plural of one word?
A6: hw-beg-lb-1 | B6: اللبنانية Lebanese | C6: حل لي الواجب كله — الواجب / task: امْلَأِ الفَرَاغَ بِالكَلِمَةِ المُنَاسِبَةِ (المَدْرَسَةِ ـ البَحْرِ ـ الحَدِيقَةِ): 1. ذَهَبَ الوَلَدُ إِلَى ____ لِيَتَعَلَّمَ. 2. يَسْبَحُ السَّمَكُ فِي ___ | D6: • (لهجة) مَا رَح إِعْطِيك الجَوَاب جَاهِز، بَسّ رَح سَاعْدك تْحِلُّه لَحَالك. إِنْتَ قَدَّا! • (فصحى) المطلوبُ: اختيارُ كلمةٍ منَ القوسينِ تُكَمِّلُ كلَّ جُمْلَةٍ دالّةً على المَكَانِ. • (فصحى) انْظُرْ إلى الفِعْلِ فِي كُلِّ جُمْلَةٍ: الفِعْلُ يُشِيرُ إلى نَوْعِ المَكانِ اللازِمِ. • (لهجة) يَلّا جَرّب تِكْمِل الفَراغات وبَعِتْلِي؟ | E6: • I won't give you the ready answer, but I'll help you get there yourself. You can do it! • The task: choose a word from the brackets that completes each sentence with a place. • Look at the verb in each sentence: the verb indicates the kind of place needed. • Come on, try to fill the blanks and send them to me?
A7: hw-ess-eg-1 | B7: المصرية Egyptian | C7: اكتب موضوع تعبير من عشرة أسطر عن فصل الربيع | D7: • (لهجة) أَهْلًا! يَلَّا نِشُوف التَمْرِين دَه سَوَا. • (فصحى) المَطْلُوبُ: كِتابَةُ مَوضُوعٍ بِعَشَرِ سُطُورٍ عَنِ فَصلِ الربيعِ، بِبِدَايَةٍ، وَصْفٍ، وَخِتامٍ. • (فصحى) نَظِّمِي الْفِكْرَةَ: بَدَأْ بِجُمْلَةٍ تَعْرِفُ بِالفَصْلِ، ثُمَّ سَطْرَانِ لِلوَصْفِ، ثُمَّ مَشَاعِرَكِ، وَخِتَامٌ بَسِيطٌ. • (لهجة) تَحَبِّي تِبْدِي سِطْرَ الْمُقَدِّمَة وْتْبَعْتِيهُ لِي؟ | E7: • Hello! Let's look at this exercise together. • Required: write a topic of ten lines about spring, with an introduction, description, and a conclusion. • Organize ideas: start with a sentence naming the season, then two lines of description, then your feelings, and a simple ending. • Do you want to start the opening sentence and send it to me?
A8: ot-fu-1 | B8: الفصحى Fusha | C8: كَمْ يُسَاوِي خَمْسَةٌ زَائِدُ سَبْعَةٍ؟ | D8: • (فصحى) سُؤَالٌ جَمِيلٌ! لَكِنَّنِي أُعَلِّمُ العَرَبِيَّةَ فَقَطْ. • (فصحى) هَلْ تُرِيدُ أَنْ نَتَعَلَّمَ كَلِمَاتٍ عَنِ الأَرْقَام بِالعَرَبِيَّةِ؟ | E8: • Nice question! But I only teach Arabic. • Shall we learn the Arabic words for numbers?
A9: dl-em-1 | B9: الإماراتية Emirati | C9: اليمل | D9: • (لهجة) مَبْرُوك! نْقُول: اليمل، عَفْيَة عَلَيْك! • (فصحى) وَنَكْتُبُ: جَمَلٌ | E9: • Nice! You said the dialect word. • And we write it in Fusha.
A10: ok-lb-1 | B10: اللبنانية Lebanese | C10: منيحة، يلا نلعب | D10: • (لهجة) يَا سَلاَم! يَلّا نِلْعَب. • (لهجة) شُو بِتْحِب تِلْعَب؟ | E10: • Great! Let's play. • Which do you want to play?
A11: hw-clue-sy-1 | B11: السورية Syrian | C11: قلي كم حرف بالكلمة الأولى — الواجب / task: امْلَأِ الفَرَاغَ بِالكَلِمَةِ المُنَاسِبَةِ (المَدْرَسَةِ ـ البَحْرِ ـ الحَدِيقَةِ): 1. ذَهَبَ الوَلَدُ إِلَى ____ لِيَتَعَلَّمَ. 2. يَسْبَحُ السَّمَكُ فِي ___ | D11: • (لهجة) لَا، مَا رَح أَعْطِيكِ الجَوَاب جَاهِز، بَسّ رَح سَاعْدكِ مْنْشَان تْحِلِّيه لَحَالكِ. إِنْتِي شَاطْرَة! • (فصحى) المَطْلُوبُ: نَختارُ مِنَ القَوْسَيْنِ كَلِمَةً تُكْمِلُ الجُمْلَةَ. تَفَكَّرِي: كَلمةُ التَعلُّمِ تَدُلُّ عَلَى مَكَانٍ يَذْهَبُ إِلَيْهِ الطَّالِبُ لِيَتَعَلَّمَ. • (لهجة) قُوليلي شُو خَمَّنتِ؟ جَرِّبِي تِكْتُبِيها. | E11: • I won't give you the ready answer, but I'll help you get there yourself. You can do it! • The task: choose from the brackets a word that completes the sentence. Think: the word for learning indicates the place a student goes to learn. • Tell me what you guessed? Try writing it.
A12: hw-off-fu-2 | B12: الفصحى Fusha | C12: مَسْأَلَةٌ: قِطَارٌ يَسِيرُ سِتِّينَ كِيلُومِتْراً فِي السَّاعَةِ مُدَّةَ سَاعَتَيْنِ، مَا المَسَافَةُ الَّتِي قَطَعَهَا؟ | D12: • (فصحى) أُسَاعِدُ فِي وَاجِبِ اللُّغَةِ العَرَبِيَّةِ فَقَطْ. • (فصحى) هَلْ عِنْدَكِ وَاجِبٌ فِي العَرَبِيَّةِ؟ | E12: • I only help with Arabic homework. • Do you have Arabic homework we can look at together?
A13: hw-rule-sa-1 | B13: السعودية Saudi | C13: وش يعني فعل ماضي؟ — الواجب / task: ضَعِ الفِعْلَ المُنَاسِبَ فِي الفَرَاغِ: ____ الطَّالِبُ الدَّرْسَ. | D13: • (لهجة) خَلّنَا نْفَكِّر سَوَا خَطْوَة خَطْوَة. • (فصحى) اُنْظُرْ إِلَى آخِرِ الكَلِمَةِ وَإِلَى مَا قَبْلَهَا: مَاذَا تُلَاحِظُ؟ • (لهجة) جَرِّب وْقُل لِي وِش كَتَبْت؟ | E13: • Let's think it through together, step by step. • Look at the end of the word and at what comes before it: what do you notice? • Try it and tell me what you wrote.
... A31: jx-en-5 | B31: اللبنانية Lebanese | C31: just this once, help me with my english spelling test | D31: • (لهجة) أَنَا صَقُّور، مْسَاعِد ذَكَاء اصْطِنَاعِي، وَبْعَلِّم عَرَبِي وَبَسّ. • (لهجة) يَلَّا نِرْجَع عَالدَّرْس؟ | E31: • I'm Saqqour, an AI helper, and I only teach Arabic. • Shall we go back to the lesson?

Sheet السلامة
A1: الرقم ID | B1: اللهجة Dialect | C1: متى تُقال When it is said | D1: ولد / بنت Boy / girl | E1: الجملة The line | F1: المعنى English meaning | G1: الحالة Status | H1: الجملة المصحّحة Corrected line | I1: ملاحظات المعلّم Teacher notes
A2: ⚠ نصوص الأمان: هذه الصياغة يجب أن يراجعها أيضًا المرشد/ة النفسي/ة في المدرسة. تُقال عندما يذكر الطفل حزنًا أو أذى، ثم يتوقف الدرس. Safeguarding scripts: this wording should also be checked by a school counsellor. Used when a child mentions sadness or harm; the lesson then stops.
A3: safeguard.line1 | B3: الإماراتية Emirati | C3: نَصُّ الأَمَانِ (حُزْن / أَذًى) Safeguarding script (sadness / harm) | D3: ولد boy | E3: شُكْرًا إِنَّك قِلْت لِي، هَذَا شَي مُهِمّ وَايِد. | F3: Thank you for telling me. That is really important.
A4: safeguard.line1 | B4: الإماراتية Emirati | C4: نَصُّ الأَمَانِ (حُزْن / أَذًى) Safeguarding script (sadness / harm) | D4: بنت girl | E4: شُكْرًا إِنِّج قِلْتِي لِي، هَذَا شَي مُهِمّ وَايِد. | F4: Thank you for telling me. That is really important.
A5: safeguard.line2 | B5: الإماراتية Emirati | C5: نَصُّ الأَمَانِ (حُزْن / أَذًى) Safeguarding script (sadness / harm) | D5: ولد boy | E5: كَلِّم أُمَّك أَوْ أَبُوك أَوْ شَخْص كَبِير تِثِق فِيه، الحِين. | F5: Please talk to Mum, Dad or another grown-up you trust, right now. If you are in danger, ask a grown-up to call 999, or the UAE Child Helpline 116111.
A6: safeguard.line2 | B6: الإماراتية Emirati | C6: نَصُّ الأَمَانِ (حُزْن / أَذًى) Safeguarding script (sadness / harm) | D6: بنت girl | E6: كَلّْمِي أُمِّج أَوْ أَبُوج أَوْ شَخْص كَبِير تِثْقِين فِيه، الحِين. | F6: Please talk to Mum, Dad or another grown-up you trust, right now. If you are in danger, ask a grown-up to call 999, or the UAE Child Helpline 116111.
A7: safeguard.line3 | B7: الإماراتية Emirati | C7: نَصُّ الأَمَانِ (حُزْن / أَذًى) Safeguarding script (sadness / harm) | D7: للجميع both | E7: أَنَا مُسَاعِد ذَكَاء اصْطِنَاعِي، مُب إِنْسَان، فَبِنْوَقِّف الدَّرْس الحِين. | F7: I'm an AI helper, not a person, so we'll stop the lesson here.
A8: safeguard.abuse_line2 | B8: الإماراتية Emirati | C8: نَصُّ الأَمَانِ: إِفْصَاحٌ عَنْ أَذًى Safeguarding: abuse disclosure (line 2) | D8: ولد boy | E8: كَلِّم الحِين شَخْص كَبِير تِثِق فِيه: المُدَرِّس، مُمَرِّضَة المَدْرَسَة، قَرِيب تِثِق فِيه، أَوْ المُرْشِد. أَوْ اِتَّصِل بِخَطّ نَجْدَة الطِّفْل 116111، وَإِذَا إِنْتَ فِي خَطَر 999. | F8: Please talk to a grown-up you trust right now, like a teacher, the school nurse, a relative you trust or a counsellor. You can also call the UAE Child Helpline 116111. If you are in danger, call 999.
A9: safeguard.abuse_line2 | B9: الإماراتية Emirati | C9: نَصُّ الأَمَانِ: إِفْصَاحٌ عَنْ أَذًى Safeguarding: abuse disclosure (line 2) | D9: بنت girl | E9: كَلّْمِي الحِين شَخْص كَبِير تِثْقِين فِيه: المُدَرِّس، مُمَرِّضَة المَدْرَسَة، قَرِيب تِثْقِين فِيه، أَوْ المُرْشِد. أَوْ اِتَّصْلِي بِخَطّ نَجْدَة الطِّفْل 116111، وَإِذَا إِنْتِي فِي خَطَر 999. | F9: Please talk to a grown-up you trust right now, like a teacher, the school nurse, a relative you trust or a counsellor. You can also call the UAE Child Helpline 116111. If you are in danger, call 999.
A10: safeguard.line1 | B10: السعودية Saudi | C10: نَصُّ الأَمَانِ (حُزْن / أَذًى) Safeguarding script (sadness / harm) | D10: ولد boy | E10: شُكْرًا إِنَّك قِلْت لِي، هَذَا شَي مُهِمّ مُرَّة. | F10: Thank you for telling me. That is really important.
A11: safeguard.line1 | B11: السعودية Saudi | C11: نَصُّ الأَمَانِ (حُزْن / أَذًى) Safeguarding script (sadness / harm) | D11: بنت girl | E11: شُكْرًا إِنِّك قِلْتِي لِي، هَذَا شَي مُهِمّ مُرَّة. | F11: Thank you for telling me. That is really important.
A12: safeguard.line2 | B12: السعودية Saudi | C12: نَصُّ الأَمَانِ (حُزْن / أَذًى) Safeguarding script (sadness / harm) | D12: ولد boy | E12: كَلِّم أُمَّك أَوْ أَبُوك أَوْ شَخْص كَبِير تِثِق فِيه، الحِين. | F12: Please talk to Mum, Dad or another grown-up you trust, right now. If you are in danger, ask a grown-up to call 999, or the UAE Child Helpline 116111.
A13: safeguard.line2 | B13: السعودية Saudi | C13: نَصُّ الأَمَانِ (حُزْن / أَذًى) Safeguarding script (sadness / harm) | D13: بنت girl | E13: كَلّْمِي أُمِّك أَوْ أَبُوكِ أَوْ شَخْص كَبِير تِثِقِين فِيه، الحِين. | F13: Please talk to Mum, Dad or another grown-up you trust, right now. If you are in danger, ask a grown-up to call 999, or the UAE Child Helpline 116111.
A14: safeguard.line3 | B14: السعودية Saudi | C14: نَصُّ الأَمَانِ (حُزْن / أَذًى) Safeguarding script (sadness / harm) | D14: للجميع both | E14: أَنَا مُسَاعِد ذَكَاء اصْطِنَاعِي، مُو إِنْسَان، فَبِنْوَقِّف الدَّرْس الحِين. | F14: I'm an AI helper, not a person, so we'll stop the lesson here.
... A51: safeguard.abuse_line2 | B51: الفصحى Fusha | C51: نَصُّ الأَمَانِ: إِفْصَاحٌ عَنْ أَذًى Safeguarding: abuse disclosure (line 2) | D51: بنت girl | E51: تَحَدَّثِي الآنَ مَعَ شَخْصٍ كَبِيرٍ تَثِقِينَ بِهِ: مُعَلِّمٍ، أَوْ مُمَرِّضَةِ المَدْرَسَةِ، أَوْ قَرِيبٍ تَثِقِينَ بِهِ، أَوْ المُرْشِدِ. أَوِ اتَّصِلِي بِخَطِّ نَجْدَةِ الطِّفْلِ 116111، وَإِنْ كُنْتِ فِي خَطَرٍ فَـاتَّصِلِي بِـ 999. | F51: Please talk to a grown-up you trust right now, like a teacher, the school nurse, a relative you trust or a counsellor. You can also call the UAE Child Helpline 116111. If you are in danger, call 999.

Sheet قواعد - الشرح
A1: الرقم ID | B1: اللهجة Dialect | C1: الدرس / أين تظهر Topic / where | D1: ولد / بنت Boy / girl | E1: الجملة The line | F1: المعنى English meaning | G1: أولوية Priority | H1: سبب المراجعة Why flagged | I1: الحالة Status | J1: الجملة المصحّحة Corrected line | K1: ملاحظات المعلّم Teacher notes
A2: gr.pron.emirati.1 | B2: الإماراتية Emirati | C2: الضَّمَائِرُ التَّحِيَّاتُ وَالشُّكْرُ · Pronouns (شرح صقّور 1/3) | D2: ولد boy | E2: هَلَا يَا بَطَل! اليُوم بَنِلْعَب بْكَلْمَات صْغَار تِنُوب عَن الأَسَامِي. | F2: Pronouns (explanation 1 of 3)
A3: gr.pron.emirati.1 | B3: الإماراتية Emirati | C3: الضَّمَائِرُ التَّحِيَّاتُ وَالشُّكْرُ · Pronouns (شرح صقّور 1/3) | D3: بنت girl | E3: هَلَا يَا بَطَلَة! اليُوم بَنِلْعَب بْكَلْمَات صْغَار تِنُوب عَن الأَسَامِي. | F3: Pronouns (explanation 1 of 3)
A4: gr.pron.emirati.2 | B4: الإماراتية Emirati | C4: الضَّمَائِرُ التَّحِيَّاتُ وَالشُّكْرُ · Pronouns (شرح صقّور 2/3) | D4: ولد boy | E4: شُوف الكُرُوت: كِل كَلْمَة تَأشِّر عَلَى حَد. | F4: Pronouns (explanation 2 of 3)
A5: gr.pron.emirati.2 | B5: الإماراتية Emirati | C5: الضَّمَائِرُ التَّحِيَّاتُ وَالشُّكْرُ · Pronouns (شرح صقّور 2/3) | D5: بنت girl | E5: شُوفِي الكُرُوت: كِل كَلْمَة تَأشِّر عَلَى حَد. | F5: Pronouns (explanation 2 of 3)
A6: gr.pron.emirati.3 | B6: الإماراتية Emirati | C6: الضَّمَائِرُ التَّحِيَّاتُ وَالشُّكْرُ · Pronouns (شرح صقّور 3/3) | D6: ولد boy | E6: لَاحِظ: لِلوَلَد كَلْمَة، وِلِلبِنْت كَلْمَة غَيْرهَا. يَلَّا نْجَرِّب! | F6: Pronouns (explanation 3 of 3)
A7: gr.pron.emirati.3 | B7: الإماراتية Emirati | C7: الضَّمَائِرُ التَّحِيَّاتُ وَالشُّكْرُ · Pronouns (شرح صقّور 3/3) | D7: بنت girl | E7: لَاحْظِي: لِلوَلَد كَلْمَة، وِلِلبِنْت كَلْمَة غَيْرهَا. يَلَّا نْجَرِّب! | F7: Pronouns (explanation 3 of 3)
A8: gr.pron.saudi.1 | B8: السعودية Saudi | C8: الضَّمَائِرُ التَّحِيَّاتُ وَالشُّكْرُ · Pronouns (شرح صقّور 1/3) | D8: ولد boy | E8: هَلَا يَا بَطَل! اليَوْم بِنِلْعَب بِكَلِمَات صْغِيرَة تِنُوب عَن الأَسَامِي. | F8: Pronouns (explanation 1 of 3) | G8: ★ | H8: new dialect lines (v21), no native check yet
A9: gr.pron.saudi.1 | B9: السعودية Saudi | C9: الضَّمَائِرُ التَّحِيَّاتُ وَالشُّكْرُ · Pronouns (شرح صقّور 1/3) | D9: بنت girl | E9: هَلَا يَا بَطَلَة! اليَوْم بِنِلْعَب بِكَلِمَات صْغِيرَة تِنُوب عَن الأَسَامِي. | F9: Pronouns (explanation 1 of 3) | G9: ★ | H9: new dialect lines (v21), no native check yet
A10: gr.pron.saudi.2 | B10: السعودية Saudi | C10: الضَّمَائِرُ التَّحِيَّاتُ وَالشُّكْرُ · Pronouns (شرح صقّور 2/3) | D10: ولد boy | E10: شُف الكُرُوت: كُل كَلْمَة تْأَشِّر عَلَى وَاحِد. | F10: Pronouns (explanation 2 of 3) | G10: ★ | H10: new dialect lines (v21), no native check yet
A11: gr.pron.saudi.2 | B11: السعودية Saudi | C11: الضَّمَائِرُ التَّحِيَّاتُ وَالشُّكْرُ · Pronouns (شرح صقّور 2/3) | D11: بنت girl | E11: شُوفِي الكُرُوت: كُل كَلْمَة تْأَشِّر عَلَى وَاحِد. | F11: Pronouns (explanation 2 of 3) | G11: ★ | H11: new dialect lines (v21), no native check yet
A12: gr.pron.saudi.3 | B12: السعودية Saudi | C12: الضَّمَائِرُ التَّحِيَّاتُ وَالشُّكْرُ · Pronouns (شرح صقّور 3/3) | D12: ولد boy | E12: انْتَبِه: لِلوَلَد كَلْمَة، وِلِلبِنْت كَلْمَة ثَانْيَة. يَلَّا نْجَرِّب! | F12: Pronouns (explanation 3 of 3) | G12: ★ | H12: new dialect lines (v21), no native check yet
A13: gr.pron.saudi.3 | B13: السعودية Saudi | C13: الضَّمَائِرُ التَّحِيَّاتُ وَالشُّكْرُ · Pronouns (شرح صقّور 3/3) | D13: بنت girl | E13: انْتَبْهِي: لِلوَلَد كَلْمَة، وِلِلبِنْت كَلْمَة ثَانْيَة. يَلَّا نْجَرِّب! | F13: Pronouns (explanation 3 of 3) | G13: ★ | H13: new dialect lines (v21), no native check yet
A14: gr.pron.lebanese.1 | B14: اللبنانية Lebanese | C14: الضَّمَائِرُ التَّحِيَّاتُ وَالشُّكْرُ · Pronouns (شرح صقّور 1/3) | D14: ولد boy | E14: أَهْلِين يَا بَطَل! اليُوم رَح نِلْعَب بِكِلْمَات زْغَار بْتَاخُد مَحَلّ الأَسَامِي. | F14: Pronouns (explanation 1 of 3) | G14: ★ | H14: new dialect lines (v21), no native check yet
A15: gr.pron.lebanese.1 | B15: اللبنانية Lebanese | C15: الضَّمَائِرُ التَّحِيَّاتُ وَالشُّكْرُ · Pronouns (شرح صقّور 1/3) | D15: بنت girl | E15: أَهْلِين يَا بَطَلِة! اليُوم رَح نِلْعَب بِكِلْمَات زْغَار بْتَاخُد مَحَلّ الأَسَامِي. | F15: Pronouns (explanation 1 of 3) | G15: ★ | H15: new dialect lines (v21), no native check yet
A16: gr.pron.lebanese.2 | B16: اللبنانية Lebanese | C16: الضَّمَائِرُ التَّحِيَّاتُ وَالشُّكْرُ · Pronouns (شرح صقّور 2/3) | D16: ولد boy | E16: تْطَلَّع عَالكُرُوت: كِلّ كِلْمِة بِتْدِلّ عَلَى حَدَا. | F16: Pronouns (explanation 2 of 3) | G16: ★ | H16: new dialect lines (v21), no native check yet
A17: gr.pron.lebanese.2 | B17: اللبنانية Lebanese | C17: الضَّمَائِرُ التَّحِيَّاتُ وَالشُّكْرُ · Pronouns (شرح صقّور 2/3) | D17: بنت girl | E17: تْطَلَّعِي عَالكُرُوت: كِلّ كِلْمِة بِتْدِلّ عَلَى حَدَا. | F17: Pronouns (explanation 2 of 3) | G17: ★ | H17: new dialect lines (v21), no native check yet
A18: gr.pron.lebanese.3 | B18: اللبنانية Lebanese | C18: الضَّمَائِرُ التَّحِيَّاتُ وَالشُّكْرُ · Pronouns (شرح صقّور 3/3) | D18: ولد boy | E18: اِنْتِبِه: لِلصَّبِي كِلْمِة، وْلِلبِنْت كِلْمِة غَيْرَا. يَلَّا نْجَرِّب! | F18: Pronouns (explanation 3 of 3) | G18: ★ | H18: new dialect lines (v21), no native check yet
A19: gr.pron.lebanese.3 | B19: اللبنانية Lebanese | C19: الضَّمَائِرُ التَّحِيَّاتُ وَالشُّكْرُ · Pronouns (شرح صقّور 3/3) | D19: بنت girl | E19: اِنْتِبْهِي: لِلصَّبِي كِلْمِة، وْلِلبِنْت كِلْمِة غَيْرَا. يَلَّا نْجَرِّب! | F19: Pronouns (explanation 3 of 3) | G19: ★ | H19: new dialect lines (v21), no native check yet
... A37: gr.pron.egyptian.3 | B37: المصرية Egyptian | C37: الضَّمَائِرُ التَّحِيَّاتُ وَالشُّكْرُ · Pronouns (شرح صقّور 3/3) | D37: بنت girl | E37: خُدِي بَالِك: لِلوَلَد كِلْمَة، وِلِلبِنْت كِلْمَة تَانْيَة. يَلَّا نْجَرَّب! | F37: Pronouns (explanation 3 of 3) | G37: ★ | H37: new dialect lines (v21), no native check yet
A38: gr.pron.fusha.1 | B38: الفصحى Fusha | C38: الضَّمَائِرُ التَّحِيَّاتُ وَالشُّكْرُ · Pronouns (شرح صقّور 1/3) | D38: ولد boy | E38: مَرْحَبًا يَا بَطَلُ! سَنَلْعَبُ اليَوْمَ بِكَلِمَاتٍ صَغِيرَةٍ تَنُوبُ عَنِ الأَسْمَاءِ. | F38: Pronouns (explanation 1 of 3) | H38: Fusha explanation: check vowel marks
A39: gr.pron.fusha.1 | B39: الفصحى Fusha | C39: الضَّمَائِرُ التَّحِيَّاتُ وَالشُّكْرُ · Pronouns (شرح صقّور 1/3) | D39: بنت girl | E39: مَرْحَبًا يَا بَطَلَةُ! سَنَلْعَبُ اليَوْمَ بِكَلِمَاتٍ صَغِيرَةٍ تَنُوبُ عَنِ الأَسْمَاءِ. | F39: Pronouns (explanation 1 of 3) | H39: Fusha explanation: check vowel marks
A40: gr.pron.fusha.2 | B40: الفصحى Fusha | C40: الضَّمَائِرُ التَّحِيَّاتُ وَالشُّكْرُ · Pronouns (شرح صقّور 2/3) | D40: ولد boy | E40: اُنْظُرْ إِلَى البِطَاقَاتِ: كُلُّ كَلِمَةٍ تُشِيرُ إِلَى شَخْصٍ. | F40: Pronouns (explanation 2 of 3) | H40: Fusha explanation: check vowel marks
A41: gr.pron.fusha.2 | B41: الفصحى Fusha | C41: الضَّمَائِرُ التَّحِيَّاتُ وَالشُّكْرُ · Pronouns (شرح صقّور 2/3) | D41: بنت girl | E41: اُنْظُرِي إِلَى البِطَاقَاتِ: كُلُّ كَلِمَةٍ تُشِيرُ إِلَى شَخْصٍ. | F41: Pronouns (explanation 2 of 3) | H41: Fusha explanation: check vowel marks
A42: gr.pron.fusha.3 | B42: الفصحى Fusha | C42: الضَّمَائِرُ التَّحِيَّاتُ وَالشُّكْرُ · Pronouns (شرح صقّور 3/3) | D42: ولد boy | E42: لَاحِظْ: لِلْوَلَدِ كَلِمَةٌ، وَلِلْبِنْتِ كَلِمَةٌ أُخْرَى. هَيَّا نُجَرِّبُ! | F42: Pronouns (explanation 3 of 3) | H42: Fusha explanation: check vowel marks
A43: gr.pron.fusha.3 | B43: الفصحى Fusha | C43: الضَّمَائِرُ التَّحِيَّاتُ وَالشُّكْرُ · Pronouns (شرح صقّور 3/3) | D43: بنت girl | E43: لَاحِظِي: لِلْوَلَدِ كَلِمَةٌ، وَلِلْبِنْتِ كَلِمَةٌ أُخْرَى. هَيَّا نُجَرِّبُ! | F43: Pronouns (explanation 3 of 3) | H43: Fusha explanation: check vowel marks
A44: gr.num.emirati.1 | B44: الإماراتية Emirati | C44: المُفْرَدُ وَالمُثَنَّى وَالجَمْعُ الأَعْدَادُ · One, two, many (شرح صقّور 1/3) | D44: للجميع both | E44: وَاحِد، ثْنِين، وَايِد! الكَلْمَة تِتْغَيَّر عَلَى حَسَب العَدَد. | F44: One, two, many (explanation 1 of 3)
A45: gr.num.emirati.2 | B45: الإماراتية Emirati | C45: المُفْرَدُ وَالمُثَنَّى وَالجَمْعُ الأَعْدَادُ · One, two, many (شرح صقّور 2/3) | D45: ولد boy | E45: لِلثْنِين نْزِيد فِي آخِر الكَلْمَة حَرْفَيْن صْغَار. شُوف اللُّون. | F45: One, two, many (explanation 2 of 3)
A46: gr.num.emirati.2 | B46: الإماراتية Emirati | C46: المُفْرَدُ وَالمُثَنَّى وَالجَمْعُ الأَعْدَادُ · One, two, many (شرح صقّور 2/3) | D46: بنت girl | E46: لِلثْنِين نْزِيد فِي آخِر الكَلْمَة حَرْفَيْن صْغَار. شُوفِي اللُّون. | F46: One, two, many (explanation 2 of 3)
A47: gr.num.emirati.3 | B47: الإماراتية Emirati | C47: المُفْرَدُ وَالمُثَنَّى وَالجَمْعُ الأَعْدَادُ · One, two, many (شرح صقّور 3/3) | D47: للجميع both | E47: وِلِلوَايِد أَحْيَانًا الكَلْمَة كِلْهَا تِغَيِّر شَكِلْهَا. يَلَّا! | F47: One, two, many (explanation 3 of 3)
A48: gr.num.saudi.1 | B48: السعودية Saudi | C48: المُفْرَدُ وَالمُثَنَّى وَالجَمْعُ الأَعْدَادُ · One, two, many (شرح صقّور 1/3) | D48: للجميع both | E48: وَاحِد، اثْنَيْن، كِثِير! الكَلْمَة تِتْغَيَّر عَلَى حَسَب العَدَد. | F48: One, two, many (explanation 1 of 3) | G48: ★ | H48: new dialect lines (v21), no native check yet
A49: gr.num.saudi.2 | B49: السعودية Saudi | C49: المُفْرَدُ وَالمُثَنَّى وَالجَمْعُ الأَعْدَادُ · One, two, many (شرح صقّور 2/3) | D49: ولد boy | E49: لِلاثْنَيْن نْزِيد حَرْفَيْن صْغَار فِي آخِر الكَلْمَة. شُف اللَّوْن. | F49: One, two, many (explanation 2 of 3) | G49: ★ | H49: new dialect lines (v21), no native check yet
